Workbook

Sheet Análise_aids_60mais
R24: POPULAÇÃO DE HOMENS E MULHERES COM MAIS DE 60 ANOS NO BRASIL ENTRE 2010 - 2024 | W24: % Por casos no Brasil | Z24: Homens_60mais | AG24: Mulheres_60mais
R25: Ano | S25: Homens_60mais | U25: Mulheres_60mais | W25: Homens% | X25: Mulheres% | Z25: Ano | AA25: Norte | AB25: Nordeste | AC25: Sul | AD25: Sudoeste | AE25: Centro Oeste | AG25: Ano | AH25: Norte | AI25: Nordeste | AJ25: Sul | AK25: Sudoeste | AL25: Centro Oeste
R26: 2010 | S26: =SUM(pop_cru_60mais!C7:AF7) -> 9123555 | U26: =SUM(pop_cru_60mais!AH7:BL7) -> 11588556 | W26: =aids_60mais_sexo!B2/Análise_aids_60mais!S26 -> 0.00010083789 | X26: =aids_60mais_sexo!C2/Análise_aids_60mais!U26 -> 5.2724429e-05 | Z26: 2010 | AA26: =SUM(pop_cru_60mais!C22:AG22) -> 543652 | AB26: =SUM(pop_cru_60mais!C37:AG37) -> 2474424 | AC26: =SUM(pop_cru_60mais!C67:AG67) -> 1479353 | AD26: =SUM(pop_cru_60mais!C52:AG52) -> 4180903 | AE26: =SUM(pop_cru_60mais!C82:AG82) -> 601037 | AG26: 2010 | AH26: =SUM(pop_cru_60mais!AH22:BL22) -> 551798 | AI26: =SUM(pop_cru_60mais!AH37:BL37) -> 3056252 | AJ26: =SUM(pop_cru_60mais!AH67:BL67) -> 1852605 | AK26: =SUM(pop_cru_60mais!AH52:BL52) -> 5474763 | AL26: =SUM(pop_cru_60mais!AH82:BL82) -> 653138
R27: 2011 | S27: =SUM(pop_cru_60mais!C8:AF8) -> 9447070 | U27: =SUM(pop_cru_60mais!AH8:BL8) -> 12017352 | W27: =aids_60mais_sexo!B3/Análise_aids_60mais!S27 -> 0.0001104046 | X27: =aids_60mais_sexo!C3/Análise_aids_60mais!U27 -> 5.866517e-05 | Z27: 2011 | AA27: =SUM(pop_cru_60mais!C23:AG23) -> 562414 | AB27: =SUM(pop_cru_60mais!C38:AG38) -> 2524585 | AC27: =SUM(pop_cru_60mais!C68:AG68) -> 1543018 | AD27: =SUM(pop_cru_60mais!C53:AG53) -> 4346681 | AE27: =SUM(pop_cru_60mais!C83:AG83) -> 626263 | AG27: 2011 | AH27: =SUM(pop_cru_60mais!AH23:BL23) -> 573838 | AI27: =SUM(pop_cru_60mais!AH38:BL38) -> 3138753 | AJ27: =SUM(pop_cru_60mais!AH68:BL68) -> 1930365 | AK27: =SUM(pop_cru_60mais!AH53:BL53) -> 5688637 | AL27: =SUM(pop_cru_60mais!AH83:BL83) -> 685759
R28: 2012 | S28: =SUM(pop_cru_60mais!C9:AF9) -> 9780621 | U28: =SUM(pop_cru_60mais!AH9:BL9) -> 12469716 | W28: =aids_60mais_sexo!B4/Análise_aids_60mais!S28 -> 0.00011226281 | X28: =aids_60mais_sexo!C4/Análise_aids_60mais!U28 -> 5.6536973e-05 | Z28: 2012 | AA28: =SUM(pop_cru_60mais!C24:AG24) -> 582704 | AB28: =SUM(pop_cru_60mais!C39:AG39) -> 2577007 | AC28: =SUM(pop_cru_60mais!C69:AG69) -> 1609763 | AD28: =SUM(pop_cru_60mais!C54:AG54) -> 4521838 | AE28: =SUM(pop_cru_60mais!C84:AG84) -> 652952 | AG28: 2012 | AH28: =SUM(pop_cru_60mais!AH24:BL24) -> 597847 | AI28: =SUM(pop_cru_60mais!AH39:BL39) -> 3226134 | AJ28: =SUM(pop_cru_60mais!AH69:BL69) -> 2012219 | AK28: =SUM(pop_cru_60mais!AH54:BL54) -> 5913169 | AL28: =SUM(pop_cru_60mais!AH84:BL84) -> 720347
R29: 2013 | S29: =SUM(pop_cru_60mais!C10:AF10) -> 10127907 | U29: =SUM(pop_cru_60mais!AH10:BL10) -> 12944842 | W29: =aids_60mais_sexo!B5/Análise_aids_60mais!S29 -> 0.00012509988 | X29: =aids_60mais_sexo!C5/Análise_aids_60mais!U29 -> 6.0410162e-05 | Z29: 2013 | AA29: =SUM(pop_cru_60mais!C25:AG25) -> 604443 | AB29: =SUM(pop_cru_60mais!C40:AG40) -> 2632152 | AC29: =SUM(pop_cru_60mais!C70:AG70) -> 1679314 | AD29: =SUM(pop_cru_60mais!C55:AG55) -> 4706164 | AE29: =SUM(pop_cru_60mais!C85:AG85) -> 681045 | AG29: 2013 | AH29: =SUM(pop_cru_60mais!AH25:BL25) -> 623699 | AI29: =SUM(pop_cru_60mais!AH40:BL40) -> 3318086 | AJ29: =SUM(pop_cru_60mais!AH70:BL70) -> 2097873 | AK29: =SUM(pop_cru_60mais!AH55:BL55) -> 6148350 | AL29: =SUM(pop_cru_60mais!AH85:BL85) -> 756834
R30: 2014 | S30: =SUM(pop_cru_60mais!C11:AF11) -> 10492106 | U30: =SUM(pop_cru_60mais!AH11:BL11) -> 13442612 | W30: =aids_60mais_sexo!B6/Análise_aids_60mais!S30 -> 0.00012237772 | X30: =aids_60mais_sexo!C6/Análise_aids_60mais!U30 -> 5.5792728e-05 | Z30: 2014 | AA30: =SUM(pop_cru_60mais!C26:AG26) -> 627509 | AB30: =SUM(pop_cru_60mais!C41:AG41) -> 2691102 | AC30: =SUM(pop_cru_60mais!C71:AG71) -> 1751373 | AD30: =SUM(pop_cru_60mais!C56:AG56) -> 4899752 | AE30: =SUM(pop_cru_60mais!C86:AG86) -> 710484 | AG30: 2014 | AH30: =SUM(pop_cru_60mais!AH26:BL26) -> 651201 | AI30: =SUM(pop_cru_60mais!AH41:BL41) -> 3414733 | AJ30: =SUM(pop_cru_60mais!AH71:BL71) -> 2186997 | AK30: =SUM(pop_cru_60mais!AH56:BL56) -> 6394535 | AL30: =SUM(pop_cru_60mais!AH86:BL86) -> 795146
R31: 2015 | S31: =SUM(pop_cru_60mais!C12:AF12) -> 10874815 | U31: =SUM(pop_cru_60mais!AH12:BL12) -> 13962679 | W31: =aids_60mais_sexo!B7/Análise_aids_60mais!S31 -> 0.00011770315 | X31: =aids_60mais_sexo!C7/Análise_aids_60mais!U31 -> 5.7295595e-05 | Z31: 2015 | AA31: =SUM(pop_cru_60mais!C27:AG27) -> 651815 | AB31: =SUM(pop_cru_60mais!C42:AG42) -> 2754592 | AC31: =SUM(pop_cru_60mais!C72:AG72) -> 1825715 | AD31: =SUM(pop_cru_60mais!C57:AG57) -> 5102325 | AE31: =SUM(pop_cru_60mais!C87:AG87) -> 741226 | AG31: 2015 | AH31: =SUM(pop_cru_60mais!AH27:BL27) -> 680234 | AI31: =SUM(pop_cru_60mais!AH42:BL42) -> 3516211 | AJ31: =SUM(pop_cru_60mais!AH72:BL72) -> 2279350 | AK31: =SUM(pop_cru_60mais!AH57:BL57) -> 6651646 | AL31: =SUM(pop_cru_60mais!AH87:BL87) -> 835238
R32: 2016 | S32: =SUM(pop_cru_60mais!C13:AF13) -> 11275943 | U32: =SUM(pop_cru_60mais!AH13:BL13) -> 14504840 | W32: =aids_60mais_sexo!B8/Análise_aids_60mais!S32 -> 0.00012114286 | X32: =aids_60mais_sexo!C8/Análise_aids_60mais!U32 -> 5.7980646e-05 | Z32: 2016 | AA32: =SUM(pop_cru_60mais!C28:AG28) -> 677476 | AB32: =SUM(pop_cru_60mais!C43:AG43) -> 2822684 | AC32: =SUM(pop_cru_60mais!C73:AG73) -> 1902323 | AD32: =SUM(pop_cru_60mais!C58:AG58) -> 5313757 | AE32: =SUM(pop_cru_60mais!C88:AG88) -> 773369 | AG32: 2016 | AH32: =SUM(pop_cru_60mais!AH28:BL28) -> 710912 | AI32: =SUM(pop_cru_60mais!AH43:BL43) -> 3622614 | AJ32: =SUM(pop_cru_60mais!AH73:BL73) -> 2374842 | AK32: =SUM(pop_cru_60mais!AH58:BL58) -> 6919309 | AL32: =SUM(pop_cru_60mais!AH88:BL88) -> 877163
R33: 2017 | S33: =SUM(pop_cru_60mais!C14:AF14) -> 11695273 | U33: =SUM(pop_cru_60mais!AH14:BL14) -> 15068686 | W33: =aids_60mais_sexo!B9/Análise_aids_60mais!S33 -> 0.00012227162 | X33: =aids_60mais_sexo!C9/Análise_aids_60mais!U33 -> 5.6209281e-05 | Z33: 2017 | AA33: =SUM(pop_cru_60mais!C29:AG29) -> 704614 | AB33: =SUM(pop_cru_60mais!C44:AG44) -> 2895430 | AC33: =SUM(pop_cru_60mais!C74:AG74) -> 1981059 | AD33: =SUM(pop_cru_60mais!C59:AG59) -> 5534100 | AE33: =SUM(pop_cru_60mais!C89:AG89) -> 806983 | AG33: 2017 | AH33: =SUM(pop_cru_60mais!AH29:BL29) -> 743435 | AI33: =SUM(pop_cru_60mais!AH44:BL44) -> 3733896 | AJ33: =SUM(pop_cru_60mais!AH74:BL74) -> 2473197 | AK33: =SUM(pop_cru_60mais!AH59:BL59) -> 7197219 | AL33: =SUM(pop_cru_60mais!AH89:BL89) -> 920939
R34: 2018 | S34: =SUM(pop_cru_60mais!C15:AF15) -> 12131978 | U34: =SUM(pop_cru_60mais!AH15:BL15) -> 15653222 | W34: =aids_60mais_sexo!B10/Análise_aids_60mais!S34 -> 0.00012990462 | X34: =aids_60mais_sexo!C10/Análise_aids_60mais!U34 -> 5.583515e-05 | Z34: 2018 | AA34: =SUM(pop_cru_60mais!C30:AG30) -> 733159 | AB34: =SUM(pop_cru_60mais!C45:AG45) -> 2973310 | AC34: =SUM(pop_cru_60mais!C75:AG75) -> 2062044 | AD34: =SUM(pop_cru_60mais!C60:AG60) -> 5761465 | AE34: =SUM(pop_cru_60mais!C90:AG90) -> 842102 | AG34: 2018 | AH34: =SUM(pop_cru_60mais!AH30:BL30) -> 777701 | AI34: =SUM(pop_cru_60mais!AH45:BL45) -> 3850581 | AJ34: =SUM(pop_cru_60mais!AH75:BL75) -> 2574632 | AK34: =SUM(pop_cru_60mais!AH60:BL60) -> 7483691 | AL34: =SUM(pop_cru_60mais!AH90:BL90) -> 966617
R35: 2019 | S35: =SUM(pop_cru_60mais!C16:AF16) -> 12584821 | U35: =SUM(pop_cru_60mais!AH16:BL16) -> 16257338 | W35: =aids_60mais_sexo!B11/Análise_aids_60mais!S35 -> 0.00012221072 | X35: =aids_60mais_sexo!C11/Análise_aids_60mais!U35 -> 5.5544149e-05 | Z35: 2019 | AA35: =SUM(pop_cru_60mais!C31:AG31) -> 762917 | AB35: =SUM(pop_cru_60mais!C46:AG46) -> 3056995 | AC35: =SUM(pop_cru_60mais!C76:AG76) -> 2145643 | AD35: =SUM(pop_cru_60mais!C61:AG61) -> 5993357 | AE35: =SUM(pop_cru_60mais!C91:AG91) -> 878825 | AG35: 2019 | AH35: =SUM(pop_cru_60mais!AH31:BL31) -> 813347 | AI35: =SUM(pop_cru_60mais!AH46:BL46) -> 3973491 | AJ35: =SUM(pop_cru_60mais!AH76:BL76) -> 2679623 | AK35: =SUM(pop_cru_60mais!AH61:BL61) -> 7776515 | AL35: =SUM(pop_cru_60mais!AH91:BL91) -> 1014362
R36: 2020 | S36: =SUM(pop_cru_60mais!C17:AF17) -> 13052317 | U36: =SUM(pop_cru_60mais!AH17:BL17) -> 16879582 | W36: =aids_60mais_sexo!B12/Análise_aids_60mais!S36 -> 9.4465986e-05 | X36: =aids_60mais_sexo!C12/Análise_aids_60mais!U36 -> 4.2655085e-05 | Z36: 2020 | AA36: =SUM(pop_cru_60mais!C32:AG32) -> 793762 | AB36: =SUM(pop_cru_60mais!C47:AG47) -> 3146760 | AC36: =SUM(pop_cru_60mais!C77:AG77) -> 2231875 | AD36: =SUM(pop_cru_60mais!C62:AG62) -> 6227913 | AE36: =SUM(pop_cru_60mais!C92:AG92) -> 917185 | AG36: 2020 | AH36: =SUM(pop_cru_60mais!AH32:BL32) -> 850231 | AI36: =SUM(pop_cru_60mais!AH47:BL47) -> 4103028 | AJ36: =SUM(pop_cru_60mais!AH77:BL77) -> 2788265 | AK36: =SUM(pop_cru_60mais!AH62:BL62) -> 8073866 | AL36: =SUM(pop_cru_60mais!AH92:BL92) -> 1064192
R37: 2021 | S37: =SUM(pop_cru_60mais!C18:AF18) -> 13533622 | U37: =SUM(pop_cru_60mais!AH18:BL18) -> 17519100 | W37: =aids_60mais_sexo!B13/Análise_aids_60mais!S37 -> 0.00011371679 | X37: =aids_60mais_sexo!C13/Análise_aids_60mais!U37 -> 4.914636e-05 | Z37: 2021 | AA37: =SUM(pop_cru_60mais!C33:AG33) -> 825748 | AB37: =SUM(pop_cru_60mais!C48:AG48) -> 3242490 | AC37: =SUM(pop_cru_60mais!C78:AG78) -> 2320497 | AD37: =SUM(pop_cru_60mais!C63:AG63) -> 6465240 | AE37: =SUM(pop_cru_60mais!C93:AG93) -> 957160 | AG37: 2021 | AH37: =SUM(pop_cru_60mais!AH33:BL33) -> 888380 | AI37: =SUM(pop_cru_60mais!AH48:BL48) -> 4239041 | AJ37: =SUM(pop_cru_60mais!AH78:BL78) -> 2900182 | AK37: =SUM(pop_cru_60mais!AH63:BL63) -> 8375416 | AL37: =SUM(pop_cru_60mais!AH93:BL93) -> 1116081
... R40: 2024 | S40: =SUM(pop_cru_60mais!C21:AF21) -> 15041309 | U40: =SUM(pop_cru_60mais!AH21:BL21) -> 19518950 | W40: =aids_60mais_sexo!B16/Análise_aids_60mais!S40 -> 0.00012332703 | X40: =aids_60mais_sexo!C16/Análise_aids_60mais!U40 -> 5.7175207e-05 | Z40: 2024 | AA40: =SUM(pop_cru_60mais!C36:AG36) -> 929062 | AB40: =SUM(pop_cru_60mais!C51:AG51) -> 3561573 | AC40: =SUM(pop_cru_60mais!C81:AG81) -> 2594909 | AD40: =SUM(pop_cru_60mais!C66:AG66) -> 7188771 | AE40: =SUM(pop_cru_60mais!C96:AG96) -> 1085949 | AG40: 2024 | AH40: =SUM(pop_cru_60mais!AH36:BL36) -> 1011232 | AI40: =SUM(pop_cru_60mais!AH51:BL51) -> 4682670 | AJ40: =SUM(pop_cru_60mais!AH81:BL81) -> 3248241 | AK40: =SUM(pop_cru_60mais!AH66:BL66) -> 9294098 | AL40: =SUM(pop_cru_60mais!AH96:BL96) -> 1282709

Sheet Notas Metodológicas e Fontes
D2: Observações que anotamos ao longo do projeto | F2: Fontes dos dados
D4: 1. Atraso na consolidação dos dados Os dados de 2024 ainda estão sendo consolidados pelo Ministério da Saúde. Casos notificados recentemente podem ainda não ter sido registrados no SINAN, o que significa que o número real de casos pode ser maior do que o apresentado. O próprio sistema avisa "dados sujeitos a revisão". | F4: 1. Casos de AIDS Ministério da Saúde — Sistema de Informação de Agravos de Notificação (SINAN) Acesso via DATASUS/TabNet Disponível em: datasus.saude.gov.br Dados consolidados até 30/09/2025. Página atualizada em 03/12/2025.
D5: 2. Subnotificação estrutural Nem todos os casos de AIDS chegam ao SINAN. Municípios menores e regiões com menor acesso à saúde tendem a ter maior subnotificação. Os números apresentados representam casos registrados, não necessariamente todos os casos existentes. | F5: 2. População brasileira Instituto Brasileiro de Geografia e Estatística (IBGE) Tabela 7358 — População, por sexo e idade Projeção da População — Ano de edição 2018 Disponível em: sidra.ibge.gov.br/Tabela/7358
D6: 3. Recorte etário — uso da Idade Detalhada O SINAN agrupa as faixas etárias em categorias que não coincidem exatamente com "60 anos ou mais". Para garantir o recorte preciso solicitado, foi utilizado o filtro de Idade Detalhada, selecionando individualmente cada ano de idade de 60 até 90 anos ou mais. | F6: 3. Referência epidemiológica Ministério da Saúde — Boletim Epidemiológico HIV/AIDS Departamento de HIV, Aids, Tuberculose, Hepatites Virais e Infecções Sexualmente Transmissíveis (Dathi) Disponível em: gov.br/aids
D7: 4. Casos com sexo ignorado Ao longo do período 2010-2024, 7 casos foram registrados sem informação de sexo na ficha de notificação do SINAN. Esses casos entram no total geral mas não aparecem nas categorias Masculino ou Feminino, gerando pequenas divergências entre os totais.
D8: 5. Casos com região ignorada ou exterior 13 casos no período total foram registrados sem região de residência identificada ou com residência fora do Brasil. Esses casos foram excluídos da análise regional.
D9: 6. Queda em 2020 — impacto da pandemia de COVID-19 A redução observada nos casos em 2020 não representa uma queda real da doença. A pandemia de COVID-19 sobrecarregou os serviços de saúde e reduziu o acesso da população aos serviços de diagnóstico e notificação, gerando subnotificação temporária. A tendência de crescimento foi retomada a partir de 2021.
D10: 7. Dados populacionais — projeções do IBGE Os dados populacionais utilizados para o cálculo das taxas são projeções baseadas no Censo Demográfico de 2022. Os anos anteriores a 2022 são retroprojeções e os anos posteriores são estimativas futuras, não contagens reais da população.

Sheet aids_60mais_estado
A1: UF Residência | B1: 2010 | C1: 2011 | D1: 2012 | E1: 2013 | F1: 2014 | G1: 2015 | H1: 2016 | I1: 2017 | J1: 2018 | K1: 2019 | L1: 2020 | M1: 2021 | N1: 2022 | O1: 2023 | P1: 2024 | Q1: Total
A2: Ignorado/Em Branco | B2: 1 | C2: 5 | D2: 3 | E2: 1 | F2: 0 | G2: 0 | H2: 0 | I2: 2 | J2: 1 | K2: 0 | L2: 0 | M2: 1 | N2: 0 | O2: 0 | P2: 0 | Q2: =SUM(aids_60mais_estado[[#This Row],[2010]:[2024]]) -> 14
A3: São Paulo | B3: 346 | C3: 370 | D3: 336 | E3: 378 | F3: 352 | G3: 380 | H3: 417 | I3: 403 | J3: 451 | K3: 398 | L3: 346 | M3: 392 | N3: 437 | O3: 429 | P3: 469 | Q3: =SUM(aids_60mais_estado[[#This Row],[2010]:[2024]]) -> 5904
A4: Rio Grande do Sul | B4: 209 | C4: 245 | D4: 259 | E4: 289 | F4: 277 | G4: 252 | H4: 275 | I4: 272 | J4: 312 | K4: 299 | L4: 245 | M4: 269 | N4: 309 | O4: 324 | P4: 343 | Q4: =SUM(aids_60mais_estado[[#This Row],[2010]:[2024]]) -> 4179
A5: Rio de Janeiro | B5: 217 | C5: 221 | D5: 231 | E5: 252 | F5: 243 | G5: 255 | H5: 212 | I5: 249 | J5: 222 | K5: 256 | L5: 210 | M5: 254 | N5: 250 | O5: 305 | P5: 280 | Q5: =SUM(aids_60mais_estado[[#This Row],[2010]:[2024]]) -> 3657
A6: Minas Gerais | B6: 148 | C6: 171 | D6: 153 | E6: 190 | F6: 169 | G6: 145 | H6: 168 | I6: 166 | J6: 183 | K6: 186 | L6: 153 | M6: 183 | N6: 183 | O6: 203 | P6: 216 | Q6: =SUM(aids_60mais_estado[[#This Row],[2010]:[2024]]) -> 2617
A7: Paraná | B7: 90 | C7: 97 | D7: 109 | E7: 97 | F7: 99 | G7: 134 | H7: 124 | I7: 122 | J7: 141 | K7: 172 | L7: 126 | M7: 130 | N7: 164 | O7: 158 | P7: 183 | Q7: =SUM(aids_60mais_estado[[#This Row],[2010]:[2024]]) -> 1946
A8: Santa Catarina | B8: 79 | C8: 100 | D8: 108 | E8: 100 | F8: 110 | G8: 162 | H8: 141 | I8: 135 | J8: 148 | K8: 125 | L8: 120 | M8: 152 | N8: 150 | O8: 145 | P8: 142 | Q8: =SUM(aids_60mais_estado[[#This Row],[2010]:[2024]]) -> 1917
A9: Bahia | B9: 56 | C9: 65 | D9: 87 | E9: 101 | F9: 98 | G9: 90 | H9: 112 | I9: 118 | J9: 122 | K9: 145 | L9: 87 | M9: 133 | N9: 133 | O9: 153 | P9: 173 | Q9: =SUM(aids_60mais_estado[[#This Row],[2010]:[2024]]) -> 1673
A10: Pará | B10: 44 | C10: 54 | D10: 63 | E10: 66 | F10: 91 | G10: 106 | H10: 99 | I10: 83 | J10: 141 | K10: 116 | L10: 88 | M10: 126 | N10: 141 | O10: 166 | P10: 165 | Q10: =SUM(aids_60mais_estado[[#This Row],[2010]:[2024]]) -> 1549
A11: Pernambuco | B11: 56 | C11: 56 | D11: 66 | E11: 96 | F11: 74 | G11: 74 | H11: 85 | I11: 109 | J11: 104 | K11: 92 | L11: 83 | M11: 102 | N11: 100 | O11: 107 | P11: 125 | Q11: =SUM(aids_60mais_estado[[#This Row],[2010]:[2024]]) -> 1329
A12: Maranhão | B12: 29 | C12: 49 | D12: 32 | E12: 55 | F12: 66 | G12: 80 | H12: 76 | I12: 73 | J12: 95 | K12: 94 | L12: 68 | M12: 88 | N12: 100 | O12: 118 | P12: 119 | Q12: =SUM(aids_60mais_estado[[#This Row],[2010]:[2024]]) -> 1142
A13: Ceará | B13: 31 | C13: 35 | D13: 49 | E13: 55 | F13: 62 | G13: 52 | H13: 76 | I13: 47 | J13: 76 | K13: 81 | L13: 54 | M13: 56 | N13: 90 | O13: 91 | P13: 127 | Q13: =SUM(aids_60mais_estado[[#This Row],[2010]:[2024]]) -> 982
... A29: Acre | B29: 0 | C29: 4 | D29: 2 | E29: 1 | F29: 3 | G29: 1 | H29: 5 | I29: 6 | J29: 3 | K29: 6 | L29: 3 | M29: 3 | N29: 5 | O29: 7 | P29: 8 | Q29: =SUM(aids_60mais_estado[[#This Row],[2010]:[2024]]) -> 57

Sheet aids_60mais_regiao
A1: Ano Diagnóstico | B1: Região Norte | C1: Região Nordeste | D1: Região Sudeste | E1: Região Sul | F1: Região Centro-Oeste | G1: Ignorado/Exterior | H1: Total
A2: 2010 | B2: 92 | C2: 237 | D2: 739 | E2: 378 | F2: 84 | G2: 1 | H2: 1531
A3: 2011 | B3: 113 | C3: 283 | D3: 794 | E3: 442 | F3: 111 | G3: 5 | H3: 1748
A4: 2012 | B4: 112 | C4: 326 | D4: 767 | E4: 476 | F4: 119 | G4: 3 | H4: 1803
A5: 2013 | B5: 148 | C5: 409 | D5: 865 | E5: 486 | F5: 140 | G5: 1 | H5: 2049
A6: 2014 | B6: 178 | C6: 407 | D6: 817 | E6: 486 | F6: 146 | G6: 0 | H6: 2034
A7: 2015 | B7: 167 | C7: 408 | D7: 835 | E7: 548 | F7: 122 | G7: 0 | H7: 2080
A8: 2016 | B8: 196 | C8: 483 | D8: 841 | E8: 540 | F8: 150 | G8: 0 | H8: 2210
A9: 2017 | B9: 196 | C9: 476 | D9: 875 | E9: 529 | F9: 200 | G9: 2 | H9: 2278
A10: 2018 | B10: 235 | C10: 551 | D10: 908 | E10: 601 | F10: 154 | G10: 1 | H10: 2450
A11: 2019 | B11: 191 | C11: 569 | D11: 899 | E11: 596 | F11: 186 | G11: 0 | H11: 2441
A12: 2020 | B12: 162 | C12: 418 | D12: 754 | E12: 491 | F12: 129 | G12: 0 | H12: 1954
A13: 2021 | B13: 234 | C13: 546 | D13: 883 | E13: 551 | F13: 185 | G13: 0 | H13: 2399
... A16: 2024 | B16: 335 | C16: 716 | D16: 1027 | E16: 668 | F16: 227 | G16: 0 | H16: 2973

Sheet aids_60mais_sexo
A1: Ano Diagnóstico | B1: Masculino | C1: Feminino | D1: Ignorado | E1: Total
A2: 2010 | B2: 920 | C2: 611 | D2: 0 | E2: 1531
A3: 2011 | B3: 1043 | C3: 705 | D3: 0 | E3: 1748
A4: 2012 | B4: 1098 | C4: 705 | D4: 0 | E4: 1803
A5: 2013 | B5: 1267 | C5: 782 | D5: 0 | E5: 2049
A6: 2014 | B6: 1284 | C6: 750 | D6: 0 | E6: 2034
A7: 2015 | B7: 1280 | C7: 800 | D7: 0 | E7: 2080
A8: 2016 | B8: 1366 | C8: 841 | D8: 3 | E8: 2210
A9: 2017 | B9: 1430 | C9: 847 | D9: 1 | E9: 2278
A10: 2018 | B10: 1576 | C10: 874 | D10: 0 | E10: 2450
A11: 2019 | B11: 1538 | C11: 903 | D11: 0 | E11: 2441
A12: 2020 | B12: 1233 | C12: 720 | D12: 1 | E12: 1954
A13: 2021 | B13: 1539 | C13: 861 | D13: 0 | E13: 2400
... A16: 2024 | B16: 1855 | C16: 1116 | D16: 2 | E16: 2973

Sheet aids_60mais_total
A1: Ano Diagnóstico | B1: Freqüência
A2: 2010 | B2: 1531
A3: 2011 | B3: 1748
A4: 2012 | B4: 1803
A5: 2013 | B5: 2049
A6: 2014 | B6: 2034
A7: 2015 | B7: 2080
A8: 2016 | B8: 2210
A9: 2017 | B9: 2278
A10: 2018 | B10: 2450
A11: 2019 | B11: 2441
A12: 2020 | B12: 1954
A13: 2021 | B13: 2400
... A16: 2024 | B16: 2973

Sheet pop_cru_60mais
A1: Tabela 7358 - População, por sexo e idade
A2: Variável - População (Pessoas)
A3: Brasil e Grande Região | B3: Ano | C3: Ano de edição da projeção x Sexo x Idade
C4: 2018
C5: Homens | AH5: Mulheres
C6: 60 anos | D6: 61 anos | E6: 62 anos | F6: 63 anos | G6: 64 anos | H6: 65 anos | I6: 66 anos | J6: 67 anos | K6: 68 anos | L6: 69 anos | M6: 70 anos | N6: 71 anos | O6: 72 anos | P6: 73 anos | Q6: 74 anos | R6: 75 anos | S6: 76 anos | T6: 77 anos | U6: 78 anos | V6: 79 anos | W6: 80 anos | X6: 81 anos | Y6: 82 anos | Z6: 83 anos | AA6: 84 anos | AB6: 85 anos | AC6: 86 anos | AD6: 87 anos | AE6: 88 anos | AF6: 89 anos | AG6: 90 anos ou mais | AH6: 60 anos | AI6: 61 anos | AJ6: 62 anos | AK6: 63 anos | AL6: 64 anos | AM6: 65 anos | AN6: 66 anos | AO6: 67 anos | AP6: 68 anos | AQ6: 69 anos | AR6: 70 anos | AS6: 71 anos | AT6: 72 anos | AU6: 73 anos | AV6: 74 anos | AW6: 75 anos | AX6: 76 anos | AY6: 77 anos | AZ6: 78 anos | BA6: 79 anos | BB6: 80 anos | BC6: 81 anos | BD6: 82 anos | BE6: 83 anos | BF6: 84 anos | BG6: 85 anos | BH6: 86 anos | BI6: 87 anos | BJ6: 88 anos | BK6: 89 anos | BL6: 90 anos ou mais
A7: Brasil | B7: 2010 | C7: 684784 | D7: 651585 | E7: 617610 | F7: 582021 | G7: 545961 | H7: 510943 | I7: 476122 | J7: 445469 | K7: 420954 | L7: 400510 | M7: 380401 | N7: 361702 | O7: 341081 | P7: 316605 | Q7: 290029 | R7: 264908 | S7: 240351 | T7: 218060 | U7: 199182 | V7: 182705 | W7: 166327 | X7: 150333 | Y7: 135007 | Z7: 120199 | AA7: 105762 | AB7: 91548 | AC7: 77412 | AD7: 63209 | AE7: 48783 | AF7: 33992 | AG7: 155814 | AH7: 775412 | AI7: 740045 | AJ7: 703981 | AK7: 666522 | AL7: 628820 | AM7: 592109 | AN7: 555425 | AO7: 523859 | AP7: 499841 | AQ7: 480756 | AR7: 461864 | AS7: 444472 | AT7: 424512 | AU7: 399586 | AV7: 371790 | AW7: 345378 | AX7: 319231 | AY7: 295403 | AZ7: 275263 | BA7: 257509 | BB7: 239258 | BC7: 220819 | BD7: 202484 | BE7: 184031 | BF7: 165224 | BG7: 145834 | BH7: 125634 | BI7: 104386 | BJ7: 81874 | BK7: 57857 | BL7: 299377
B8: 2011 | C8: 707938 | D8: 672582 | E8: 639959 | F8: 606587 | G8: 571626 | H8: 534009 | I8: 497605 | J8: 463693 | K8: 433840 | L8: 409961 | M8: 387498 | N8: 365526 | O8: 347558 | P8: 327749 | Q8: 304232 | R8: 275905 | S8: 249316 | T8: 226208 | U8: 205231 | V8: 187461 | W8: 169576 | X8: 152038 | Y8: 137418 | Z8: 123398 | AA8: 109850 | AB8: 94681 | AC8: 80047 | AD8: 67673 | AE8: 55256 | AF8: 42649 | AG8: 155891 | AH8: 804620 | AI8: 767292 | AJ8: 732303 | AK8: 696614 | AL8: 659537 | AM8: 620449 | AN8: 582497 | AO8: 546402 | AP8: 515341 | AQ8: 491719 | AR8: 470722 | AS8: 450015 | AT8: 433076 | AU8: 413630 | AV8: 389346 | AW8: 359538 | AX8: 331343 | AY8: 306274 | AZ8: 283420 | BA8: 264102 | BB8: 243919 | BC8: 223506 | BD8: 206284 | BE8: 189159 | BF8: 171915 | BG8: 151275 | BH8: 130554 | BI8: 112473 | BJ8: 93451 | BK8: 73301 | BL8: 303275
B9: 2012 | C9: 732605 | D9: 695570 | E9: 660831 | F9: 628763 | G9: 595968 | H9: 559354 | I9: 520341 | J9: 484869 | K9: 451815 | L9: 422729 | M9: 396876 | N9: 372596 | O9: 351473 | P9: 334201 | Q9: 315157 | R9: 289655 | S9: 259925 | T9: 234877 | U9: 213111 | V9: 193354 | W9: 174186 | X9: 155228 | Y9: 139171 | Z9: 125781 | AA9: 112938 | AB9: 98501 | AC9: 82955 | AD9: 70124 | AE9: 59271 | AF9: 48396 | AG9: 163643 | AH9: 835191 | AI9: 796372 | AJ9: 759433 | AK9: 724798 | AL9: 689473 | AM9: 650945 | AN9: 610585 | AO9: 573230 | AP9: 537710 | AQ9: 507135 | AR9: 481653 | AS9: 458879 | AT9: 438701 | AU9: 422189 | AV9: 403230 | AW9: 376748 | AX9: 345198 | AY9: 318142 | AZ9: 294079 | BA9: 272148 | BB9: 250425 | BC9: 228173 | BD9: 209076 | BE9: 192970 | BF9: 176950 | BG9: 157679 | BH9: 135737 | BI9: 117140 | BJ9: 100918 | BK9: 83849 | BL9: 320960
B10: 2013 | C10: 758086 | D10: 720059 | E10: 683657 | F10: 649497 | G10: 617978 | H10: 583416 | I10: 545309 | J10: 507269 | K10: 472691 | L10: 440455 | M10: 409469 | N10: 381866 | O10: 358504 | P10: 338179 | Q10: 321575 | R10: 300294 | S10: 273137 | T10: 245108 | U10: 221487 | V10: 200972 | W10: 179866 | X10: 159654 | Y10: 142276 | Z10: 127558 | AA10: 115277 | AB10: 101433 | AC10: 86474 | AD10: 72812 | AE10: 61540 | AF10: 52009 | AG10: 175211 | AH10: 866117 | AI10: 826807 | AJ10: 788382 | AK10: 751810 | AL10: 717519 | AM10: 680674 | AN10: 640808 | AO10: 601067 | AP10: 564296 | AQ10: 529328 | AR10: 496952 | AS10: 469764 | AT10: 447557 | AU10: 427877 | AV10: 411776 | AW10: 390418 | AX10: 361991 | AY10: 331689 | AZ10: 305698 | BA10: 282590 | BB10: 258314 | BC10: 234561 | BD10: 213721 | BE10: 195838 | BF10: 180752 | BG10: 162570 | BH10: 141790 | BI10: 122058 | BJ10: 105333 | BK10: 90744 | BL10: 346041
B11: 2014 | C11: 784923 | D11: 745357 | E11: 707953 | F11: 672163 | G11: 638567 | H11: 605206 | I11: 569041 | J11: 531868 | K11: 494757 | L11: 461035 | M11: 426873 | N11: 394229 | O11: 367651 | P11: 345167 | Q11: 325598 | R11: 306643 | S11: 283427 | T11: 257798 | U11: 231351 | V11: 209054 | W11: 187152 | X11: 165066 | Y11: 146525 | Z11: 130566 | AA11: 117060 | AB11: 103695 | AC11: 89214 | AD11: 76042 | AE11: 64020 | AF11: 54105 | AG11: 188114 | AH11: 897662 | AI11: 857594 | AJ11: 818675 | AK11: 780628 | AL11: 744414 | AM11: 708539 | AN11: 670284 | AO11: 631020 | AP11: 591885 | AQ11: 555669 | AR11: 518907 | AS11: 484909 | AT11: 458381 | AU11: 436717 | AV11: 417515 | AW11: 398928 | AX11: 375400 | AY11: 348068 | AZ11: 318944 | BA11: 293963 | BB11: 268473 | BC11: 242249 | BD11: 219974 | BE11: 200435 | BF11: 183666 | BG11: 166332 | BH11: 146486 | BI11: 127765 | BJ11: 109986 | BK11: 94909 | BL11: 374235
B12: 2015 | C12: 812330 | D12: 771978 | E12: 733069 | F12: 696268 | G12: 661068 | H12: 625613 | I12: 590571 | J12: 555266 | K12: 518988 | L12: 482772 | M12: 447066 | N12: 411237 | O12: 379787 | P12: 354177 | Q12: 332528 | R12: 310704 | S12: 289675 | T12: 267745 | U12: 243536 | V12: 218556 | W12: 194871 | X12: 171951 | Y12: 151666 | Z12: 134638 | AA12: 119968 | AB12: 105454 | AC12: 91365 | AD12: 78591 | AE12: 66985 | AF12: 56392 | AG12: 200858 | AH12: 929313 | AI12: 889009 | AJ12: 849317 | AK12: 810779 | AL12: 773099 | AM12: 735277 | AN12: 697927 | AO12: 660244 | AP12: 621564 | AQ12: 583018 | AR12: 544933 | AS12: 506565 | AT12: 473368 | AU12: 447477 | AV12: 426327 | AW12: 404721 | AX12: 383843 | AY12: 361212 | AZ12: 334919 | BA12: 306907 | BB12: 279525 | BC12: 252057 | BD12: 227451 | BE12: 206545 | BF12: 188199 | BG12: 169275 | BH12: 150171 | BI12: 132256 | BJ12: 115354 | BK12: 99305 | BL12: 402722
B13: 2016 | C13: 840362 | D13: 799176 | E13: 759472 | F13: 721191 | G13: 684985 | H13: 647900 | I13: 610748 | J13: 576536 | K13: 542061 | L13: 506638 | M13: 468383 | N13: 430951 | O13: 396405 | P13: 366088 | Q13: 341397 | R13: 317538 | S13: 293750 | T13: 273875 | U13: 253148 | V13: 230263 | W13: 203920 | X13: 179240 | Y13: 158168 | Z13: 139516 | AA13: 123851 | AB13: 108229 | AC13: 93074 | AD13: 80627 | AE13: 69350 | AF13: 59101 | AG13: 213666 | AH13: 961194 | AI13: 920516 | AJ13: 880603 | AK13: 841282 | AL13: 803112 | AM13: 763784 | AN13: 724464 | AO13: 687669 | AP13: 650535 | AQ13: 612420 | AR13: 571964 | AS13: 532204 | AT13: 494729 | AU13: 462301 | AV13: 437019 | AW13: 413481 | AX13: 389681 | AY13: 369582 | AZ13: 347797 | BA13: 322486 | BB13: 292077 | BC13: 262717 | BD13: 236917 | BE13: 213799 | BF13: 194160 | BG13: 173704 | BH13: 153116 | BI13: 135837 | BJ13: 119633 | BK13: 104346 | BL13: 431711
B14: 2017 | C14: 869161 | D14: 826986 | E14: 786458 | F14: 747387 | G14: 709715 | H14: 671586 | I14: 632781 | J14: 596485 | K14: 563070 | L14: 529392 | M14: 491775 | N14: 451761 | O14: 415643 | P14: 382324 | Q14: 353078 | R14: 326222 | S14: 300455 | T14: 277948 | U14: 259149 | V14: 239540 | W14: 215042 | X14: 187761 | Y14: 165043 | Z14: 145650 | AA14: 128484 | AB14: 111874 | AC14: 95678 | AD14: 82271 | AE14: 71264 | AF14: 61290 | AG14: 226913 | AH14: 993152 | AI14: 952280 | AJ14: 911984 | AK14: 872437 | AL14: 833482 | AM14: 793617 | AN14: 752762 | AO14: 714003 | AP14: 677747 | AQ14: 641147 | AR14: 601017 | AS14: 558839 | AT14: 519994 | AU14: 483369 | AV14: 451684 | AW14: 424069 | AX14: 398374 | AY14: 375441 | AZ14: 356082 | BA14: 335095 | BB14: 307159 | BC14: 274796 | BD14: 247184 | BE14: 222932 | BF14: 201184 | BG14: 179460 | BH14: 157402 | BI14: 138748 | BJ14: 123091 | BK14: 108411 | BL14: 461744
B15: 2018 | C15: 897323 | D15: 855562 | E15: 814051 | F15: 774162 | G15: 735696 | H15: 696072 | I15: 656180 | J15: 618261 | K15: 582790 | L15: 550137 | M15: 514110 | N15: 474578 | O15: 435962 | P15: 401096 | Q15: 368941 | R15: 337598 | S15: 308904 | T15: 284512 | U15: 263201 | V15: 245407 | W15: 223904 | X15: 198194 | Y15: 173064 | Z15: 152138 | AA15: 134264 | AB15: 116204 | AC15: 99051 | AD15: 84703 | AE15: 72833 | AF15: 63080 | AG15: 240102 | AH15: 1024733 | AI15: 984121 | AJ15: 943622 | AK15: 903688 | AL15: 864512 | AM15: 823808 | AN15: 782364 | AO15: 742091 | AP15: 703884 | AQ15: 668144 | AR15: 629419 | AS15: 587462 | AT15: 546238 | AU15: 508264 | AV15: 472459 | AW15: 438521 | AX15: 408824 | AY15: 384049 | AZ15: 361949 | BA15: 343285 | BB15: 319416 | BC15: 289273 | BD15: 258810 | BE15: 232812 | BF15: 209985 | BG15: 186197 | BH15: 162895 | BI15: 142875 | BJ15: 125943 | BK15: 111736 | BL15: 491843
B16: 2019 | C16: 924629 | D16: 883507 | E16: 842388 | F16: 801531 | G16: 762248 | H16: 721775 | I16: 680363 | J16: 641369 | K16: 604297 | L16: 569622 | M16: 534499 | N16: 496395 | O16: 458216 | P16: 420928 | Q16: 387259 | R16: 352987 | S16: 319912 | T16: 292726 | U16: 269612 | V16: 249421 | W16: 229579 | X16: 206565 | Y16: 182857 | Z16: 159681 | AA16: 140377 | AB16: 121570 | AC16: 103025 | AD16: 87822 | AE16: 75091 | AF16: 64570 | AG16: 252916 | AH16: 1055906 | AI16: 1015569 | AJ16: 975327 | AK16: 935193 | AL16: 895612 | AM16: 854653 | AN16: 812318 | AO16: 771460 | AP16: 731744 | AQ16: 694079 | AR16: 656117 | AS16: 615451 | AT16: 574430 | AU16: 534118 | AV16: 496975 | AW16: 458920 | AX16: 422993 | AY16: 394354 | AZ16: 370460 | BA16: 349151 | BB16: 327472 | BC16: 301098 | BD16: 272697 | BE16: 243994 | BF16: 219495 | BG16: 194575 | BH16: 169281 | BI16: 148101 | BJ16: 129901 | BK16: 114506 | BL16: 521388
B17: 2020 | C17: 950842 | D17: 910596 | E17: 870114 | F17: 829622 | G17: 789389 | H17: 748047 | I17: 705739 | J17: 665238 | K17: 627118 | L17: 590858 | M17: 553665 | N17: 516343 | O17: 479522 | P17: 442634 | Q17: 406614 | R17: 370743 | S17: 334732 | T17: 303366 | U17: 277588 | V17: 255676 | W17: 233524 | X17: 211994 | Y17: 190756 | Z17: 168870 | AA17: 147475 | AB17: 127235 | AC17: 107919 | AD17: 91464 | AE17: 77968 | AF17: 66666 | AG17: 265178 | AH17: 1086195 | AI17: 1046613 | AJ17: 1006636 | AK17: 966750 | AL17: 926971 | AM17: 885558 | AN17: 842930 | AO17: 801170 | AP17: 760876 | AQ17: 721710 | AR17: 681773 | AS17: 641779 | AT17: 602002 | AU17: 561881 | AV17: 522450 | AW17: 482943 | AX17: 442928 | AY17: 408249 | AZ17: 380612 | BA17: 357552 | BB17: 333307 | BC17: 308974 | BD17: 284105 | BE17: 257313 | BF17: 230240 | BG17: 203624 | BH17: 177160 | BI17: 154143 | BJ17: 134861 | BK17: 118290 | BL17: 549987
B18: 2021 | C18: 977405 | D18: 936628 | E18: 896984 | F18: 857122 | G18: 817240 | H18: 774896 | I18: 731671 | J18: 690289 | K18: 650675 | L18: 613387 | M18: 574544 | N18: 535113 | O18: 499030 | P18: 463438 | Q18: 427785 | R18: 389500 | S18: 351814 | T18: 317640 | U18: 287871 | V18: 263410 | W18: 239559 | X18: 215832 | Y18: 195947 | Z18: 176321 | AA18: 156099 | AB18: 133804 | AC18: 113080 | AD18: 95925 | AE18: 81304 | AF18: 69309 | AG18: 277513 | AH18: 1116174 | AI18: 1076777 | AJ18: 1037550 | AK18: 997917 | AL18: 958378 | AM18: 916729 | AN18: 873594 | AO18: 831542 | AP18: 790349 | AQ18: 750601 | AR18: 709101 | AS18: 667096 | AT18: 627959 | AU18: 589046 | AV18: 549789 | AW18: 507920 | AX18: 466368 | AY18: 427722 | AZ18: 394227 | BA18: 367546 | BB18: 341562 | BC18: 314760 | BD18: 291789 | BE18: 268307 | BF18: 243015 | BG18: 213824 | BH18: 185660 | BI18: 161546 | BJ18: 140565 | BK18: 122989 | BL18: 578698
B19: 2022 | C19: 1004443 | D19: 962988 | E19: 922825 | F19: 883774 | G19: 844506 | H19: 802452 | I19: 758170 | J19: 715876 | K19: 675396 | L19: 636641 | M19: 596682 | N19: 555543 | O19: 517410 | P19: 482512 | Q19: 448096 | R19: 410008 | S19: 369857 | T19: 334071 | U19: 301611 | V19: 273348 | W19: 246981 | X19: 221599 | Y19: 199663 | Z19: 181272 | AA19: 163126 | AB19: 141767 | AC19: 119050 | AD19: 100627 | AE19: 85367 | AF19: 72367 | AG19: 290381 | AH19: 1146287 | AI19: 1106637 | AJ19: 1067587 | AK19: 1028702 | AL19: 989407 | AM19: 947939 | AN19: 904529 | AO19: 861969 | AP19: 820479 | AQ19: 779837 | AR19: 737674 | AS19: 694046 | AT19: 652940 | AU19: 614634 | AV19: 576554 | AW19: 534718 | AX19: 490738 | AY19: 450585 | AZ19: 413247 | BA19: 380887 | BB19: 351339 | BC19: 322827 | BD19: 297501 | BE19: 275792 | BF19: 253606 | BG19: 225927 | BH19: 195227 | BI19: 169517 | BJ19: 147518 | BK19: 128364 | BL19: 608342
... B21: 2024 | C21: 1050259 | D21: 1014201 | E21: 975612 | F21: 935371 | G21: 896378 | H21: 855594 | I21: 811994 | J21: 768873 | K21: 726449 | L21: 685934 | M21: 643480 | N21: 599543 | O21: 558576 | P21: 520056 | Q21: 484351 | R21: 447812 | S21: 408525 | T21: 370388 | U21: 334107 | V21: 301776 | W21: 269074 | X21: 237634 | Y21: 211849 | Z21: 190100 | AA21: 171299 | AB21: 152711 | AC21: 132223 | AD21: 112598 | AE21: 94583 | AF21: 79959 | AG21: 318955 | AH21: 1193970 | AI21: 1162947 | AJ21: 1127197 | AK21: 1088224 | AL21: 1049829 | AM21: 1009255 | AN21: 966121 | AO21: 923403 | AP21: 881117 | AQ21: 839671 | AR21: 796161 | AS21: 750748 | AT21: 707305 | AU21: 665469 | AV21: 626080 | AW21: 585718 | AX21: 542510 | AY21: 499868 | AZ21: 458751 | BA21: 421218 | BB21: 382308 | BC21: 344888 | BD21: 314597 | BE21: 289084 | BF21: 266418 | BG21: 243024 | BH21: 216020 | BI21: 189061 | BJ21: 163391 | BK21: 141889 | BL21: 672708
A22: Norte | B22: 2010 | C22: 41262 | D22: 38679 | E22: 36337 | F22: 34327 | G22: 32553 | H22: 30827 | I22: 29190 | J22: 27547 | K22: 25835 | L22: 24100 | M22: 22455 | N22: 20876 | O22: 19350 | P22: 17883 | Q22: 16470 | R22: 15111 | S22: 13805 | T22: 12553 | U22: 11355 | V22: 10212 | W22: 9128 | X22: 8105 | Y22: 7142 | Z22: 6243 | AA22: 5407 | AB22: 4635 | AC22: 3931 | AD22: 3293 | AE22: 2725 | AF22: 2227 | AG22: 10089 | AH22: 39973 | AI22: 37335 | AJ22: 35007 | AK22: 33122 | AL22: 31547 | AM22: 30006 | AN22: 28557 | AO22: 27088 | AP22: 25517 | AQ22: 23900 | AR22: 22380 | AS22: 20928 | AT22: 19516 | AU22: 18136 | AV22: 16795 | AW22: 15501 | AX22: 14247 | AY22: 13058 | AZ22: 11941 | BA22: 10889 | BB22: 9878 | BC22: 8917 | BD22: 8000 | BE22: 7134 | BF22: 6310 | BG22: 5531 | BH22: 4796 | BI22: 4099 | BJ22: 3445 | BK22: 2829 | BL22: 15416
B23: 2011 | C23: 43172 | D23: 40448 | E23: 37912 | F23: 35618 | G23: 33648 | H23: 31772 | I23: 29942 | J23: 28357 | K23: 26758 | L23: 25096 | M23: 23209 | N23: 21436 | O23: 19928 | P23: 18471 | Q23: 17070 | R23: 15569 | S23: 14137 | T23: 12915 | U23: 11745 | V23: 10621 | W23: 9407 | X23: 8263 | Y23: 7338 | Z23: 6467 | AA23: 5653 | AB23: 4791 | AC23: 4003 | AD23: 3395 | AE23: 2844 | AF23: 2356 | AG23: 10073 | AH23: 42146 | AI23: 39417 | AJ23: 36818 | AK23: 34521 | AL23: 32659 | AM23: 31015 | AN23: 29413 | AO23: 27993 | AP23: 26554 | AQ23: 25015 | AR23: 23287 | AS23: 21667 | AT23: 20266 | AU23: 18896 | AV23: 17557 | AW23: 16123 | AX23: 14748 | AY23: 13556 | AZ23: 12424 | BA23: 11361 | BB23: 10219 | BC23: 9139 | BD23: 8250 | BE23: 7405 | BF23: 6606 | BG23: 5734 | BH23: 4924 | BI23: 4269 | BJ23: 3650 | BK23: 3067 | BL23: 15139
B24: 2012 | C24: 45245 | D24: 42325 | E24: 39656 | F24: 37169 | G24: 34921 | H24: 32844 | I24: 30872 | J24: 29095 | K24: 27553 | L24: 26001 | M24: 24181 | N24: 22162 | O24: 20473 | P24: 19030 | Q24: 17640 | R24: 16144 | S24: 14576 | T24: 13232 | U24: 12089 | V24: 10996 | W24: 9786 | X24: 8523 | Y24: 7487 | Z24: 6652 | AA24: 5860 | AB24: 5013 | AC24: 4141 | AD24: 3465 | AE24: 2932 | AF24: 2463 | AG24: 10178 | AH24: 44445 | AI24: 41572 | AJ24: 38882 | AK24: 36314 | AL24: 34049 | AM24: 32121 | AN24: 30411 | AO24: 28842 | AP24: 27449 | AQ24: 26041 | AR24: 24382 | AS24: 22561 | AT24: 20991 | AU24: 19634 | AV24: 18304 | AW24: 16867 | AX24: 15350 | AY24: 14045 | AZ24: 12908 | BA24: 11833 | BB24: 10673 | BC24: 9465 | BD24: 8465 | BE24: 7645 | BF24: 6865 | BG24: 6012 | BH24: 5116 | BI24: 4391 | BJ24: 3807 | BK24: 3255 | BL24: 15152
B25: 2013 | C25: 47296 | D25: 44368 | E25: 41504 | F25: 38886 | G25: 36448 | H25: 34097 | I25: 31923 | J25: 30005 | K25: 28279 | L25: 26779 | M25: 25063 | N25: 23102 | O25: 21176 | P25: 19557 | Q25: 18182 | R25: 16693 | S25: 15120 | T25: 13654 | U25: 12392 | V25: 11324 | W25: 10141 | X25: 8871 | Y25: 7729 | Z25: 6790 | AA25: 6034 | AB25: 5200 | AC25: 4341 | AD25: 3586 | AE25: 2998 | AF25: 2541 | AG25: 10364 | AH25: 46703 | AI25: 43852 | AJ25: 41015 | AK25: 38361 | AL25: 35827 | AM25: 33497 | AN25: 31507 | AO25: 29830 | AP25: 28292 | AQ25: 26927 | AR25: 25395 | AS25: 23633 | AT25: 21868 | AU25: 20347 | AV25: 19030 | AW25: 17596 | AX25: 16072 | AY25: 14628 | AZ25: 13386 | BA25: 12301 | BB25: 11128 | BC25: 9896 | BD25: 8778 | BE25: 7854 | BF25: 7096 | BG25: 6256 | BH25: 5372 | BI25: 4572 | BJ25: 3923 | BK25: 3401 | BL25: 15356
B26: 2014 | C26: 49276 | D26: 46390 | E26: 43513 | F26: 40707 | G26: 38139 | H26: 35595 | I26: 33152 | J26: 31037 | K26: 29169 | L26: 27494 | M26: 25819 | N26: 23957 | O26: 22082 | P26: 20240 | Q26: 18692 | R26: 17214 | S26: 15643 | T26: 14170 | U26: 12797 | V26: 11611 | W26: 10451 | X26: 9202 | Y26: 8051 | Z26: 7016 | AA26: 6162 | AB26: 5361 | AC26: 4506 | AD26: 3765 | AE26: 3107 | AF26: 2598 | AG26: 10593 | AH26: 48832 | AI26: 46090 | AJ26: 43277 | AK26: 40477 | AL26: 37855 | AM26: 35254 | AN26: 32867 | AO26: 30916 | AP26: 29270 | AQ26: 27762 | AR26: 26269 | AS26: 24625 | AT26: 22920 | AU26: 21208 | AV26: 19732 | AW26: 18304 | AX26: 16782 | AY26: 15327 | AZ26: 13951 | BA26: 12768 | BB26: 11579 | BC26: 10332 | BD26: 9186 | BE26: 8151 | BF26: 7299 | BG26: 6476 | BH26: 5599 | BI26: 4808 | BJ26: 4093 | BK26: 3511 | BL26: 15681
B27: 2015 | C27: 51208 | D27: 48337 | E27: 45509 | F27: 42685 | G27: 39934 | H27: 37254 | I27: 34618 | J27: 32240 | K27: 30183 | L27: 28366 | M27: 26517 | N27: 24691 | O27: 22908 | P27: 21112 | Q27: 19353 | R27: 17705 | S27: 16143 | T27: 14668 | U27: 13288 | V27: 11998 | W27: 10720 | X27: 9491 | Y27: 8357 | Z27: 7313 | AA27: 6375 | AB27: 5477 | AC27: 4654 | AD27: 3909 | AE27: 3267 | AF27: 2695 | AG27: 10840 | AH27: 50882 | AI27: 48206 | AJ27: 45495 | AK27: 42720 | AL27: 39955 | AM27: 37261 | AN27: 34600 | AO27: 32258 | AP27: 30345 | AQ27: 28732 | AR27: 27094 | AS27: 25488 | AT27: 23894 | AU27: 22239 | AV27: 20577 | AW27: 18992 | AX27: 17468 | AY27: 16017 | AZ27: 14628 | BA27: 13315 | BB27: 12030 | BC27: 10762 | BD27: 9603 | BE27: 8540 | BF27: 7581 | BG27: 6671 | BH27: 5804 | BI27: 5021 | BJ27: 4309 | BK27: 3672 | BL27: 16075
B28: 2016 | C28: 53289 | D28: 50245 | E28: 47428 | F28: 44652 | G28: 41881 | H28: 39018 | I28: 36241 | J28: 33676 | K28: 31362 | L28: 29360 | M28: 27370 | N28: 25366 | O28: 23619 | P28: 21913 | Q28: 20196 | R28: 18340 | S28: 16609 | T28: 15143 | U28: 13765 | V28: 12466 | W28: 11085 | X28: 9743 | Y28: 8625 | Z28: 7594 | AA28: 6649 | AB28: 5674 | AC28: 4757 | AD28: 4045 | AE28: 3394 | AF28: 2838 | AG28: 11133 | AH28: 53089 | AI28: 50239 | AJ28: 47600 | AK28: 44920 | AL28: 42183 | AM28: 39339 | AN28: 36581 | AO28: 33972 | AP28: 31671 | AQ28: 29793 | AR28: 28053 | AS28: 26300 | AT28: 24745 | AU28: 23195 | AV28: 21588 | AW28: 19818 | AX28: 18138 | AY28: 16683 | AZ28: 15300 | BA28: 13972 | BB28: 12554 | BC28: 11192 | BD28: 10015 | BE28: 8936 | BF28: 7951 | BG28: 6937 | BH28: 5987 | BI28: 5212 | BJ28: 4508 | BK28: 3870 | BL28: 16571
B29: 2017 | C29: 55506 | D29: 52302 | E29: 49314 | F29: 46548 | G29: 43827 | H29: 40934 | I29: 37970 | J29: 35267 | K29: 32773 | L29: 30519 | M29: 28338 | N29: 26192 | O29: 24274 | P29: 22602 | Q29: 20971 | R29: 19148 | S29: 17213 | T29: 15592 | U29: 14217 | V29: 12921 | W29: 11526 | X29: 10080 | Y29: 8862 | Z29: 7843 | AA29: 6910 | AB29: 5921 | AC29: 4935 | AD29: 4137 | AE29: 3518 | AF29: 2952 | AG29: 11502 | AH29: 55446 | AI29: 52443 | AJ29: 49630 | AK29: 47020 | AL29: 44377 | AM29: 41550 | AN29: 38640 | AO29: 35927 | AP29: 33372 | AQ29: 31113 | AR29: 29102 | AS29: 27250 | AT29: 25549 | AU29: 24037 | AV29: 22534 | AW29: 20802 | AX29: 18943 | AY29: 17337 | AZ29: 15945 | BA29: 14624 | BB29: 13187 | BC29: 11694 | BD29: 10422 | BE29: 9332 | BF29: 8327 | BG29: 7287 | BH29: 6236 | BI29: 5382 | BJ29: 4684 | BK29: 4056 | BL29: 17187
B30: 2018 | C30: 57708 | D30: 54492 | E30: 51347 | F30: 48415 | G30: 45701 | H30: 42850 | I30: 39848 | J30: 36965 | K30: 34334 | L30: 31903 | M30: 29470 | N30: 27129 | O30: 25075 | P30: 23239 | Q30: 21636 | R30: 19893 | S30: 17982 | T30: 16167 | U30: 14645 | V30: 13355 | W30: 11953 | X30: 10489 | Y30: 9174 | Z30: 8066 | AA30: 7139 | AB30: 6159 | AC30: 5154 | AD30: 4297 | AE30: 3602 | AF30: 3063 | AG30: 11909 | AH30: 57751 | AI30: 54795 | AJ30: 51829 | AK30: 49048 | AL30: 46474 | AM30: 43732 | AN30: 40826 | AO30: 37972 | AP30: 35304 | AQ30: 32798 | AR30: 30410 | AS30: 28286 | AT30: 26488 | AU30: 24836 | AV30: 23365 | AW30: 21732 | AX30: 19897 | AY30: 18118 | AZ30: 16582 | BA30: 15252 | BB30: 13815 | BC30: 12294 | BD30: 10907 | BE30: 9718 | BF30: 8706 | BG30: 7639 | BH30: 6561 | BI30: 5614 | BJ30: 4846 | BK30: 4217 | BL30: 17889
B31: 2019 | C31: 59819 | D31: 56664 | E31: 53507 | F31: 50419 | G31: 47540 | H31: 44690 | I31: 41726 | J31: 38801 | K31: 35994 | L31: 33432 | M31: 30815 | N31: 28224 | O31: 25981 | P31: 24015 | Q31: 22256 | R31: 20529 | S31: 18692 | T31: 16899 | U31: 15192 | V31: 13761 | W31: 12363 | X31: 10884 | Y31: 9552 | Z31: 8356 | AA31: 7347 | AB31: 6368 | AC31: 5368 | AD31: 4494 | AE31: 3742 | AF31: 3140 | AG31: 12347 | AH31: 59891 | AI31: 57082 | AJ31: 54161 | AK31: 51232 | AL31: 48480 | AM31: 45812 | AN31: 42979 | AO31: 40128 | AP31: 37324 | AQ31: 34701 | AR31: 32068 | AS31: 29567 | AT31: 27506 | AU31: 25758 | AV31: 24152 | AW31: 22545 | AX31: 20798 | AY31: 19043 | AZ31: 17339 | BA31: 15871 | BB31: 14420 | BC31: 12891 | BD31: 11471 | BE31: 10184 | BF31: 9073 | BG31: 7996 | BH31: 6886 | BI31: 5914 | BJ31: 5063 | BK31: 4370 | BL31: 18642
B32: 2020 | C32: 61871 | D32: 58742 | E32: 55645 | F32: 52546 | G32: 49512 | H32: 46497 | I32: 43523 | J32: 40638 | K32: 37791 | L32: 35055 | M32: 32299 | N32: 29524 | O32: 27041 | P32: 24889 | Q32: 23011 | R32: 21127 | S32: 19297 | T32: 17572 | U32: 15886 | V32: 14282 | W32: 12747 | X32: 11264 | Y32: 9919 | Z32: 8704 | AA32: 7619 | AB32: 6557 | AC32: 5555 | AD32: 4684 | AE32: 3920 | AF32: 3263 | AG32: 12782 | AH32: 61985 | AI32: 59203 | AJ32: 56426 | AK32: 53537 | AL32: 50645 | AM32: 47790 | AN32: 45035 | AO32: 42247 | AP32: 39447 | AQ32: 36693 | AR32: 33934 | AS32: 31188 | AT32: 28758 | AU32: 26755 | AV32: 25055 | AW32: 23314 | AX32: 21589 | AY32: 19915 | AZ32: 18238 | BA32: 16603 | BB32: 15014 | BC32: 13467 | BD32: 12040 | BE32: 10718 | BF32: 9517 | BG32: 8340 | BH32: 7217 | BI32: 6216 | BJ32: 5340 | BK32: 4571 | BL32: 19434
B33: 2021 | C33: 64017 | D33: 60765 | E33: 57691 | F33: 54652 | G33: 51607 | H33: 48431 | I33: 45292 | J33: 42397 | K33: 39586 | L33: 36811 | M33: 33877 | N33: 30958 | O33: 28297 | P33: 25915 | Q33: 23854 | R33: 21854 | S33: 19869 | T33: 18148 | U33: 16527 | V33: 14940 | W33: 13235 | X33: 11623 | Y33: 10272 | Z33: 9045 | AA33: 7940 | AB33: 6808 | AC33: 5723 | AD33: 4850 | AE33: 4089 | AF33: 3423 | AG33: 13252 | AH33: 64152 | AI33: 61276 | AJ33: 58527 | AK33: 55779 | AL33: 52925 | AM33: 49931 | AN33: 46983 | AO33: 44275 | AP33: 41538 | AQ33: 38785 | AR33: 35886 | AS33: 33015 | AT33: 30342 | AU33: 27979 | AV33: 26032 | AW33: 24195 | AX33: 22338 | AY33: 20686 | AZ33: 19078 | BA33: 17475 | BB33: 15717 | BC33: 14033 | BD33: 12590 | BE33: 11255 | BF33: 10024 | BG33: 8757 | BH33: 7537 | BI33: 6522 | BJ33: 5619 | BK33: 4826 | BL33: 20303
B34: 2022 | C34: 66218 | D34: 62879 | E34: 59686 | F34: 56668 | G34: 53679 | H34: 50488 | I34: 47185 | J34: 44127 | K34: 41307 | L34: 38569 | M34: 35583 | N34: 32480 | O34: 29683 | P34: 27128 | Q34: 24847 | R34: 22664 | S34: 20562 | T34: 18694 | U34: 17075 | V34: 15550 | W34: 13851 | X34: 12076 | Y34: 10608 | Z34: 9373 | AA34: 8254 | AB34: 7101 | AC34: 5948 | AD34: 5002 | AE34: 4237 | AF34: 3574 | AG34: 13783 | AH34: 66403 | AI34: 63424 | AJ34: 60580 | AK34: 57861 | AL34: 55147 | AM34: 52182 | AN34: 49095 | AO34: 46195 | AP34: 43538 | AQ34: 40847 | AR34: 37942 | AS34: 34921 | AT34: 32130 | AU34: 29528 | AV34: 27228 | AW34: 25148 | AX34: 23191 | AY34: 21412 | AZ34: 19830 | BA34: 18290 | BB34: 16553 | BC34: 14701 | BD34: 13126 | BE34: 11780 | BF34: 10532 | BG34: 9232 | BH34: 7925 | BI34: 6817 | BJ34: 5903 | BK34: 5087 | BL34: 21283
... B36: 2024 | C36: 71155 | D36: 67377 | E36: 63907 | F36: 60686 | G36: 57608 | H36: 54473 | I36: 51191 | J36: 47952 | K36: 44814 | L36: 41913 | M36: 38926 | N36: 35782 | O36: 32744 | P36: 29887 | Q36: 27314 | R36: 24740 | S36: 22238 | T36: 20091 | U36: 18224 | V36: 16571 | W36: 14916 | X36: 13177 | Y36: 11555 | Z36: 10072 | AA36: 8852 | AB36: 7664 | AC36: 6465 | AD36: 5436 | AE36: 4556 | AF36: 3829 | AG36: 14947 | AH36: 71523 | AI36: 68059 | AJ36: 64920 | AK36: 62004 | AL36: 59226 | AM36: 56418 | AN36: 53484 | AO36: 50472 | AP36: 47488 | AQ36: 44687 | AR36: 41907 | AS36: 38913 | AT36: 35962 | AU36: 33094 | AV36: 30451 | AW36: 27787 | AX36: 25247 | AY36: 23143 | AZ36: 21336 | BA36: 19707 | BB36: 18037 | BC36: 16241 | BD36: 14510 | BE36: 12896 | BF36: 11520 | BG36: 10176 | BH36: 8801 | BI36: 7585 | BJ36: 6511 | BK36: 5600 | BL36: 23527
A37: Nordeste | B37: 2010 | C37: 166847 | D37: 162057 | E37: 156268 | F37: 148724 | G37: 140156 | H37: 131921 | I37: 123596 | J37: 116317 | K37: 110739 | L37: 106221 | M37: 101613 | N37: 97318 | O37: 92124 | P37: 85360 | Q37: 77714 | R37: 70449 | S37: 63198 | T37: 57051 | U37: 52642 | V37: 49387 | W37: 45978 | X37: 42563 | Y37: 39290 | Z37: 36058 | AA37: 32778 | AB37: 29346 | AC37: 25675 | AD37: 21667 | AE37: 17221 | AF37: 12247 | AG37: 61899 | AH37: 193458 | AI37: 187019 | AJ37: 179894 | AK37: 171579 | AL37: 162632 | AM37: 153917 | AN37: 145030 | AO37: 137524 | AP37: 132185 | AQ37: 128171 | AR37: 124044 | AS37: 120327 | AT37: 115220 | AU37: 107759 | AV37: 98911 | AW37: 90484 | AX37: 81977 | AY37: 74770 | AZ37: 69688 | BA37: 65978 | BB37: 61949 | BC37: 57790 | BD37: 53702 | BE37: 49561 | BF37: 45248 | BG37: 40640 | BH37: 35618 | BI37: 30060 | BJ37: 23852 | BK37: 16867 | BL37: 100398
B38: 2011 | C38: 169111 | D38: 163530 | E38: 158840 | F38: 153170 | G38: 145778 | H38: 136812 | I38: 128220 | J38: 120129 | K38: 113061 | L38: 107641 | M38: 102491 | N38: 97291 | O38: 93181 | P38: 88209 | Q38: 81735 | R38: 73631 | S38: 66001 | T38: 59203 | U38: 53444 | V38: 49316 | W38: 45533 | X38: 41654 | Y38: 38566 | Z38: 35598 | AA38: 32669 | AB38: 29080 | AC38: 25412 | AD38: 22229 | AE38: 18762 | AF38: 14917 | AG38: 59371 | AH38: 198139 | AI38: 190978 | AJ38: 184628 | AK38: 177591 | AL38: 169376 | AM38: 160075 | AN38: 151036 | AO38: 142308 | AP38: 134937 | AQ38: 129698 | AR38: 125116 | AS38: 120441 | AT38: 116832 | AU38: 111873 | AV38: 104626 | AW38: 95290 | AX38: 86457 | AY38: 78324 | AZ38: 71434 | BA38: 66578 | BB38: 62190 | BC38: 57539 | BD38: 53674 | BE38: 49877 | BF38: 46022 | BG38: 41233 | BH38: 36260 | BI38: 31777 | BJ38: 26820 | BK38: 21288 | BL38: 96336
B39: 2012 | C39: 171855 | D39: 165788 | E39: 160325 | F39: 155727 | G39: 150171 | H39: 142344 | I39: 133019 | J39: 124672 | K39: 116803 | L39: 109938 | M39: 103899 | N39: 98181 | O39: 93200 | P39: 89265 | Q39: 84504 | R39: 77488 | S39: 69033 | T39: 61876 | U39: 55501 | V39: 50100 | W39: 45499 | X39: 41291 | Y39: 37777 | Z39: 34974 | AA39: 32283 | AB39: 29013 | AC39: 25217 | AD39: 22033 | AE39: 19272 | AF39: 16268 | AG39: 59691 | AH39: 203353 | AI39: 195652 | AJ39: 188585 | AK39: 182312 | AL39: 175363 | AM39: 166766 | AN39: 157142 | AO39: 148262 | AP39: 139691 | AQ39: 132447 | AR39: 126665 | AS39: 121549 | AT39: 117009 | AU39: 113502 | AV39: 108681 | AW39: 100868 | AX39: 91128 | AY39: 82678 | AZ39: 74894 | BA39: 68304 | BB39: 62823 | BC39: 57844 | BD39: 53514 | BE39: 49920 | BF39: 46381 | BG39: 42011 | BH39: 36867 | BI39: 32420 | BJ39: 28411 | BK39: 23980 | BL39: 97112
B40: 2013 | C40: 175395 | D40: 168518 | E40: 162577 | F40: 157220 | G40: 152717 | H40: 146674 | I40: 138445 | J40: 129381 | K40: 121269 | L40: 113612 | M40: 106162 | N40: 99574 | O40: 94095 | P40: 89324 | Q40: 85559 | R40: 80163 | S40: 72700 | T40: 64768 | U40: 58049 | V40: 52067 | W40: 46259 | X40: 41296 | Y40: 37478 | Z40: 34291 | AA40: 31748 | AB40: 28701 | AC40: 25192 | AD40: 21894 | AE40: 19129 | AF40: 16731 | AG40: 61164 | AH40: 208827 | AI40: 200852 | AJ40: 193249 | AK40: 186265 | AL40: 180069 | AM40: 172720 | AN40: 163773 | AO40: 154314 | AP40: 145591 | AQ40: 137167 | AR40: 129407 | AS40: 123122 | AT40: 118148 | AU40: 113734 | AV40: 110326 | AW40: 104847 | AX40: 96542 | AY40: 87216 | AZ40: 79122 | BA40: 71671 | BB40: 64518 | BC40: 58514 | BD40: 53872 | BE40: 49834 | BF40: 46485 | BG40: 42408 | BH40: 37641 | BI40: 33032 | BJ40: 29045 | BK40: 25455 | BL40: 100320
B41: 2014 | C41: 180204 | D41: 172034 | E41: 165291 | F41: 159466 | G41: 154216 | H41: 149204 | I41: 142705 | J41: 134705 | K41: 125889 | L41: 118000 | M41: 109756 | N41: 101790 | O41: 95474 | P41: 90227 | Q41: 85651 | R41: 81211 | S41: 75264 | T41: 68257 | U41: 60806 | V41: 54495 | W41: 48119 | X41: 42025 | Y41: 37518 | Z41: 34049 | AA41: 31155 | AB41: 28256 | AC41: 24956 | AD41: 21900 | AE41: 19032 | AF41: 16632 | AG41: 62815 | AH41: 214754 | AI41: 206311 | AJ41: 198431 | AK41: 190919 | AL41: 184017 | AM41: 177407 | AN41: 169681 | AO41: 160887 | AP41: 151588 | AQ41: 143015 | AR41: 134081 | AS41: 125854 | AT41: 119736 | AU41: 114900 | AV41: 110606 | AW41: 106504 | AX41: 100430 | AY41: 92470 | AZ41: 83532 | BA41: 75779 | BB41: 67767 | BC41: 60168 | BD41: 54564 | BE41: 50234 | BF41: 46463 | BG41: 42571 | BH41: 38071 | BI41: 33792 | BJ41: 29652 | BK41: 26074 | BL41: 104475
B42: 2015 | C42: 185875 | D42: 176791 | E42: 168781 | F42: 162165 | G42: 156457 | H42: 150707 | I42: 145219 | J42: 138896 | K42: 131113 | L42: 122536 | M42: 114045 | N42: 105289 | O42: 97646 | P42: 91589 | Q42: 86559 | R42: 81342 | S42: 76298 | T42: 70714 | U42: 64125 | V42: 57126 | W42: 50406 | X42: 43760 | Y42: 38212 | Z42: 34119 | AA42: 30960 | AB42: 27760 | AC42: 24601 | AD42: 21724 | AE42: 19065 | AF42: 16568 | AG42: 64144 | AH42: 221012 | AI42: 212220 | AJ42: 203872 | AK42: 196085 | AL42: 188658 | AM42: 181346 | AN42: 174342 | AO42: 166748 | AP42: 158104 | AQ42: 148961 | AR42: 139857 | AS42: 130465 | AT42: 122455 | AU42: 116503 | AV42: 111796 | AW42: 106841 | AX42: 102091 | AY42: 96267 | AZ42: 88633 | BA42: 80062 | BB42: 71720 | BC42: 63273 | BD42: 56176 | BE42: 50942 | BF42: 46896 | BG42: 42614 | BH42: 38290 | BI42: 34242 | BJ42: 30392 | BK42: 26670 | BL42: 108678
...
